Workbook

Sheet MainTable
A1: Results Data in [Sample Results] for Test Name : | B1: LC-MS
A2: Analyte : | B2: Acrylamide
A3: Select Report Type (Spike, Ref…) : | B3: Low Spike
A4: Select Units (ppm, µg/kg, g/L…) : | B4: µg/kg
A5: Enter Expected Analyte Concentration For Analytes : | B5: 90
A6: MDL - Optional (From Mean of Previous Low Spikes) :
A7: Select # of Significant figures : | B7: 2
A8: =IF(B8=2,IF(B24<9,"Number of Samples = "&B24&" Try Selecting 1-tail test","Select One or Two tail Grubbs’ Test (α: 0.05) :"),"Select One or Two tail Grubbs’ Test (α: 0.05) :") -> Select One or Two tail Grubbs’ Test (α: 0.05) : | B8: 1
A9: Total Number of Results | B9: =IF(B38>0,B24+B38&" ("&B38&" Excluded)",B24) -> 9 (1 Excluded)
A10: ST DEV σ of Results | B10: =FIXED(B26,B27) -> 6.377
A11: RSD% (CV) | B11: =B28 -> 0.076676586
A12: bias as %age (100 - Recovery) | B12: =IFERROR(IF(B3="Blank",0,(1-B22)),0) -> 0.075916667
A13: MDL Factor (n-1 Degrees Freedom) | B13: =VLOOKUP(B24-1,Distributions!A2:B42,2,TRUE) -> 2.998
A14: Units - 1 Part in This Value | B14: =VLOOKUP(B4,Units!$A1:$B14,2,FALSE) -> 1000000000
A15: Predicted Horwitz "Expected Value" as RSD% | B15: =IF(B5/B14<1.2*0.0000001,22,IF(B5/B14<=0.138,2*POWER(B5/B14,-0.15),POWER(B5/B14,-0.5))) -> 22
A16: Horwitz Ratio (Ideally 0.3≤ HorRat ≤1) | B16: =((B11*100)/B15) -> 0.34852994
A17: =IF(B17=B36,"Ymax (Maximum Value) may be a Grubbs' Outlier","Ymax (Maximum Value)") -> Ymax (Maximum Value) | B17: =MAX(SampleResults!B1:B31) -> 89.84
A18: =IF(B18=B36,"Ymin (Minimum Value) may be a Grubbs' Outlier","Ymin (Minimum Value)") -> Ymin (Minimum Value) | B18: =MIN(SampleResults!B1:B31) -> 72.11
A19: ="Result to "&B7&" Significant figures" -> Result to 2 Significant figures | B19: =FIXED(B25,((-1*INT(LOG10(B25)))-1)+B7,TRUE) -> 83
A20: MDL = (MDL Factor x SD) | B20: =IFERROR(IF(B3="Blank",0,B51),0) -> 21
A21: PQL (Practical Quantitation limit) | B21: =IFERROR(IF(B3="Blank",0,B45),0) -> 62
A22: % Recovery | B22: =IFERROR(IF(B3="Blank","Blank",(B25)/B5),100) -> 0.92408333
A24: Number of Results included in Calculations | B24: =COUNT(SampleResults!B1:B31) -> 8
A25: Raw Mean of Samples (Ymv) | B25: =IF(B24>0,AVERAGE(SampleResults!B1:B31),0) -> 83.1675
A26: Raw ST DEV σ of Results | B26: =IF(B24>1,STDEV(SampleResults!B1:B31),0) -> 6.3774754
A27: Number of Decimal places for DISPLAYED Data | B27: =IF(B5<1,INT(ABS(LOG10(B5)))+B7+2,IF(B5<10,4,IF(B5<100,3,IF(B5<1000,2,IF(B5<10000,1,0))))) -> 3
A28: Raw Relative SD | B28: =IF(B24>0,B10/B25,0) -> 0.076676586
A30: Ymax - Ymv | B30: =B17-B25 -> 6.6725
A31: Ymv - Ymin | B31: =B25-B18 -> 11.0575
A32: =IF(B8=1,"Sig Value: 1-sided","Sig Value: 2-sided") -> Sig Value: 1-sided | B32: =IF(B8=1,(2*(1-0.95))/(B24),((1-0.95))/(B24)) -> 0.0125
A33: G (min) | B33: =(B25-B18)/B26 -> 1.7338366
A34: G (max) | B34: =(B17-B25)/B26 -> 1.0462604
A35: G Critical | B35: =VLOOKUP(B24,Distributions!A5:D42,(2+B8)) -> 2.032
A36: Check if This Result is an Outlier? | B36: =IFERROR(IF(B33<B35,IF(B34<B35,0,B17),B18),0) -> 0
A38: Number of Excluded Results | B38: =COUNTIF(SampleResults!B1:B31,"*") -> 1
A39: Raw uncertainty at 95Conf - u | B39: =SQRT(POWER(B26,2)+POWER(B26/SQRT(B24),2)) -> 6.7643342
A40: Raw MDL = (MDL Factor x SD) | B40: =IF(ISBLANK(B6),B13*B26,B6) -> 19.119671
A41: Bias | B41: =B39*2 -> 13.528668
A42: Raw bias (Mean - Spike) | B42: =B25-B5 -> -6.8325
A43: MDL Corrected | B43: =IF(ISTEXT(B6),B19,IFERROR(B40/B22,IF(B6>0,B6,B19))) -> 20.690419
...

Sheet SampleResults
A1: S1 | B1: 86.38
A2: S2 | B2: 87.79
A3: S3 | B3: 77.94
A4: S4 | B4: 72.11
A5: S5 Duplicate S3 | B5: 78.56
A6: S6 | B6: 89.84
A7: S7 | B7: 89.3
A8: S8 | B8: 83.42
A9: S9 (Outlier?) | B9: ?58.97

Sheet Report
A2: ="Summary Report - "&B17 -> Summary Report - Low Spike
A4: Report Date | B4: 44676
A5: Laboratory Name | B5: Tim’s Testing & Consulting Laboratory Pty Ltd
A6: Address | B6: 15a Bridge Street
B7: Some-Town, STATE, X100
A9: Contact | B9: Tim Strutt
B10: tim@timstrutt.com
A12: Authorised By | B12: Saga Brondam
A15: Analyte | B15: =MainTable!B2 -> Acrylamide
A16: Number of Samples in This Report | B16: =MainTable!B24 -> 8
A17: =IF(B17<>"Certified Reference","Report Type","Reporting Type NOT yet installed...") -> Report Type | B17: =MainTable!B3 -> Low Spike
A18: =IF(B17="Reference Material","Reference Material Type (PT, CRM, Lab., etc.)","")
A19: =IF(B17="Reference Material","ReferenceID: (PT, Batch/SerialNo., Date, etc.)","")
A20: =IF(B17="Reference Material","Reference Material Uncertainty: "&MainTable!B4&" (info only)","")
A21: =B17&" Level" -> Low Spike Level | B21: =MainTable!B5&" "&MainTable!B4 -> 90 µg/kg
A22: =MainTable!$A22 -> % Recovery | B22: =IF(MainTable!B3="Blank","Blank",MainTable!B22) -> 0.92408333
A23: RSD% (CV) | B23: =MainTable!B11 -> 0.076676586
A24: Bias as a %age | B24: =MainTable!B12 -> 0.075916667
A25: Is Bias Satisfactory? (Y/N) : | B25: Yes
A26: =MainTable!$A16 -> Horwitz Ratio (Ideally 0.3≤ HorRat ≤1) | B26: =MainTable!B16 -> 0.34852994
A27: Is Horwitz Ratio Satisfactory? (Y/N) : | B27: Yes
A30: ="Result to "&MainTable!B7&" Significant figures" -> Result to 2 Significant figures | B30: =MainTable!B19&" "&MainTable!B4 -> 83 µg/kg
A31: Method Detection Limit (MDL) | B31: =IF(MainTable!B3="Blank",0,MainTable!B20&" "&MainTable!B4) -> 21 µg/kg
A32: Practical Quantitation Limit (PQL) | B32: =IF(MainTable!B3="Blank",0,MainTable!B21&" "&MainTable!B4) -> 62 µg/kg
A33: =IF(B27&B25="YesYes","Result Corrected for Recovery Bias","Horwitz Ratio / Bias Not Approved") -> Result Corrected for Recovery Bias | B33: =MainTable!B53 -> 90 ± 21 µg/kg

Sheet Distributions
A1: Student’s t-test | C1: Grubbs’ test 𝜶 0.05
A2: Limit | B2: 0.99 | C2: 1-sided | D2: 2-sided
A3: 1 | B3: 31.82
A4: 2 | B4: 6.965
A5: 3 | B5: 4.541 | C5: 1.153 | D5: 1.155
A6: 4 | B6: 3.747 | C6: 1.463 | D6: 1.481
A7: 5 | B7: 3.365 | C7: 1.672 | D7: 1.715
A8: 6 | B8: 3.143 | C8: 1.822 | D8: 1.887
A9: 7 | B9: 2.998 | C9: 1.938 | D9: 2.02
A10: 8 | B10: 2.896 | C10: 2.032 | D10: 2.126
A11: 9 | B11: 2.821 | C11: 2.11 | D11: 2.215
A12: 10 | B12: 2.764 | C12: 2.176 | D12: 2.29
A13: 11 | B13: 2.718 | C13: 2.234 | D13: 2.355
A14: 12 | B14: 2.681 | C14: 2.285 | D14: 2.412
A15: 13 | B15: 2.65 | C15: 2.331 | D15: 2.462
A16: 14 | B16: 2.624 | C16: 2.371 | D16: 2.507
... A40: 1000 | B40: 2.33 | C40: 4 | D40: 4.5

Sheet Units
A1: Unit | B1: NumericValue
A2: ppm | B2: 1000000
A3: ppb | B3: 1000000000
A4: ppt | B4: 1000000000000
A5: mg/kg | B5: 1000000
A6: µg/kg | B6: 1000000000
A7: ng/kg | B7: 1000000000000
A8: mg/L | B8: 1000000
A9: µg/L | B9: 1000000000
A10: ng/L | B10: 1000000000000
A11: pg/L | B11: 1e+15
A12: g/L | B12: 100
A13: percent | B13: 100
A14: drops/floz | B14: 568

Sheet Notes
A1: This spreadsheet may be useful to assist Laboratory Analysts and Assessors ensure compliance with ISO/ IEC 17025:2017. The revised standard requires Measurement Uncertainty (MU) of chemical test results to be available. It is designed to help produce necessary information by using sample blanks, spikes, and comparisons with reference materials. Sample "Low Spikes" could be used to determine Recoveries and Method Detection Limits. Spikes establish MUs at different concentrations with different matrices. It may be helpful when developing new methods or for "novel" analytes and matrices. An authorised report for a single analyte can be printed.
A2: Created with Apple "Numbers" Version 13, and Microsoft "Excel" 2013, spreadsheet programs - Using only "Cell Functions". No "Code", Macros, or Hyperlinks are used - It should be “Safe” to distribute…
A3: The spreadsheet uses some conventions: In [MainTable] cells where the user is expected to input data have blue text : labels, bold blue indicates that a selection is made from a list. Default look-ups are grey. Checks have [pale backgrounds]; Warnings have [darker backgrounds]; and Failure/Out-of-range warnings have [red backgrounds]; Replaced MDLs or Significances have [blue backgrounds] Important data is purple.
A4: Getting Started: The sheets are [MainTable], [SampleResults], [Report], [Distributions] and [Units], and [Notes]. The last three are "look-ups" or information. Data should be added or changed as outlined below…
A5: [MainTable]: Used to set the parameters of the Test:- Fill in the Instrument/Test name that was used to create the results. Fill in the Analyte Name for your set of results Select Report Type from the drop-down - This will produce different a different [Report] for each type. Select Units from the drop-down - This will change the Horwitz Ratio (larger concentrations should give higher precision). Enter 'Spike Value' - Values between 0.00001 and 10,000,000. MDL (From Mean of Previous Low Spikes) - If a value is entered, it will be used instead of the Results calculation. Select Number of Significant figures - Usually 2 - 1 may be useful if near Quantitation limits, 3 for special precision. Select One or two tail Grubbs’ Test (α: 0.05) - Normally 1; 2 is not recommended for <9 approved Results. 1 calculates the right and left tails separately, the furthest from the mean is used for the "one outlier" hypothesis. Now go to the [SampleResults] Sheet… [SampleResults]: Used to add SampleID and Results. There are 2 columns:- Used to Add/Edit SampleID (or Paste from another spreadsheet). Used to Add/Edit Results (or Paste from another spreadsheet). Possible Outliers can be indicated by adding text e.g. Changing 77 to ?77 or 77! This will cause the possible Outlier to be ignored by the Horwitz and Grubbs calculations. The sheet can have many rows, but normally 3-11 are used (5, or more recommended). [Report]: Used to display or print a formal report:- The Report Date, Laboratory Name, Address, Contact, and Authorised data can be edited. Check that the Bias and Horwitz Ratio are satisfactory - An Outlier can increase these values… [Distributions]: Used to calculate Method Detection Limit (t-test) and Grubbs’ critical value:- This is not editable. It is recommended that the user consults the NIST and RSC papers, referenced in the text at the bottom of the sheet, for further background information. [Units]: Used to calculate scale of Horwitz values, and in [Report] and [Calculations - Main Table]:- It is normally Locked, but any changes must be reflected in [MU Calculations] "Select Units" drop-down.
A6: For further information, please consult these References:- Planning and Reporting Method Validation Studies; Supplement to EURACHEM Guide on the Fitness for Purpose of Analytical Methods, First edition 2019 Blanks in Method Validation, Supplement to EURACHEM Guide The Fitness for Purpose of Analytical Methods, First Edition 2019
A7: The password to unlock individual MS Excel sheets and cells is "timstrutt" (no "quotes"). Apple Sheets use Locked "Shapes".
A8: The [MainTable] uses "hidden" rows with a red font - Changing or deleting them will cause breakages...
A9: Warning: The calculations are based upon standard literature methods, but some approximations have been used. See the references described above for background information.
A10: This spread-sheet is "Public Domain". Anyone is free to copy, modify, publish, use, or distribute it for any purpose, commercial or non-commercial, and by any means. The author is retired; carries out "Pro Bono" work only; and does not accept any responsibility for any loss caused by the use of, or failure to use, this spreadsheet. Please do not remove my name, copyright & version information.
A11: Version: 2026-06-02 - ©Tim Strutt.
